Traceback (most recent call last):
  File "/home/sour/Sumo/2025-08-11-19-32-20/./RL_controller.py", line 119, in <module>
    run_simulation()
  File "/home/sour/Sumo/2025-08-11-19-32-20/./RL_controller.py", line 91, in run_simulation
    traci.simulationStep()
  File "/home/sour/Sumo/2025-08-11-19-32-20/venv/lib/python3.12/site-packages/traci/main.py", line 200, in simulationStep
    connection.check().simulationStep(step)
  File "/home/sour/Sumo/2025-08-11-19-32-20/venv/lib/python3.12/site-packages/traci/connection.py", line 370, in simulationStep
    result = self._sendCmd(tc.CMD_SIMSTEP, None, None, "D", step)
             ^^^^^^^^^^^^^^^^^^^^^^^^^^^^^^^^^^^^^^^^^^^^^^^^^^^^
  File "/home/sour/Sumo/2025-08-11-19-32-20/venv/lib/python3.12/site-packages/traci/connection.py", line 232, in _sendCmd
    return self._sendExact()
           ^^^^^^^^^^^^^^^^^
  File "/home/sour/Sumo/2025-08-11-19-32-20/venv/lib/python3.12/site-packages/traci/connection.py", line 137, in _sendExact
    raise FatalTraCIError("Connection closed by SUMO.")
traci.exceptions.FatalTraCIError: Connection closed by SUMO.
