Traceback (most recent call last):
  File "/home/sour/Sumo/2025-08-11-19-32-20/venv/lib/python3.12/site-packages/traci/main.py", line 97, in connect
    return connection.Connection(host, port, proc, traceFile, traceGetters, label)
           ^^^^^^^^^^^^^^^^^^^^^^^^^^^^^^^^^^^^^^^^^^^^^^^^^^^^^^^^^^^^^^^^^^^^^^^
  File "/home/sour/Sumo/2025-08-11-19-32-20/venv/lib/python3.12/site-packages/traci/connection.py", line 83, in __init__
    self._socket.connect((host, port))
ConnectionRefusedError: [Errno 111] Connection refused

During handling of the above exception, another exception occurred:

Traceback (most recent call last):
  File "/home/sour/Sumo/2025-08-11-19-32-20/Node=1&Lane=1/./GA.py", line 98, in <module>
    fitnesses = list(map(toolbox.evaluate, pop))
                ^^^^^^^^^^^^^^^^^^^^^^^^^^^^^^^^
  File "/home/sour/Sumo/2025-08-11-19-32-20/Node=1&Lane=1/./GA.py", line 47, in evaluate
    traci.start(sumoCmd)
  File "/home/sour/Sumo/2025-08-11-19-32-20/venv/lib/python3.12/site-packages/traci/main.py", line 147, in start
    result = init(sumoPort, numRetries, "localhost", label, sumoProcess, doSwitch, traceFile, traceGetters)
             ^^^^^^^^^^^^^^^^^^^^^^^^^^^^^^^^^^^^^^^^^^^^^^^^^^^^^^^^^^^^^^^^^^^^^^^^^^^^^^^^^^^^^^^^^^^^^^
  File "/home/sour/Sumo/2025-08-11-19-32-20/venv/lib/python3.12/site-packages/traci/main.py", line 116, in init
    con = connect(port, numRetries, host, proc, 1, traceFile, traceGetters, label)
          ^^^^^^^^^^^^^^^^^^^^^^^^^^^^^^^^^^^^^^^^^^^^^^^^^^^^^^^^^^^^^^^^^^^^^^^^
  File "/home/sour/Sumo/2025-08-11-19-32-20/venv/lib/python3.12/site-packages/traci/main.py", line 105, in connect
    time.sleep(waitBetweenRetries)
KeyboardInterrupt
